Traceback (most recent call last):
  File "statistics.py", line 14, in <module>
    c= subprocess.call(["python", "sudoku_solver.py", "-heur", '3', "-type", t])
  File "/usr/lib/python3.8/subprocess.py", line 340, in call
    with Popen(*popenargs, **kwargs) as p:
  File "/usr/lib/python3.8/subprocess.py", line 854, in __init__
    self._execute_child(args, executable, preexec_fn, close_fds,
  File "/usr/lib/python3.8/subprocess.py", line 1702, in _execute_child
    raise child_exception_type(errno_num, err_msg, err_filename)
FileNotFoundError: [Errno 2] No such file or directory: 'python'
